<?xml version="1.0"?>

<!-- Spruzzino --> 


<robot name ="sprayer" xmlns:xacro="http://www.ros.org/wiki/xacro">

    <xacro:macro name="fake_inertial">
        <inertial>
          <origin xyz="0 0 0" rpy="0 0 0"/>
          <mass value="1e-5"/>
          <inertia
	      ixx="1e-6" ixy="0.0" ixz="0.0"
	      iyy="1e-6" iyz="0.0"
	      izz="1e-6"/>
        </inertial>
    </xacro:macro>

<joint name="sprayer_to_sprayerbase" type="fixed">
        <parent link="sprayerbase"/>
        <child link="base_plate"/>   
        <origin xyz="0.1205 0 0.05" rpy="0 0 -${PI/2}" />
    </joint>

    
	
    <link name="base_plate">
		<visual>
			<origin rpy="0 0 0" xyz="0 0 0" />
			<geometry>
				<box size="0.06 0.221 0.004"/>
			</geometry>
		</visual>
		
<!--		<collision>-->
<!--			<origin rpy="0 0 0" xyz="0 0 0"/>-->
<!--			<geometry>-->
<!--				<box size="0.060 0.2210 0.0040"/>-->
<!--			</geometry>-->
<!--		</collision>-->
<!--		-->
<!--		<inertial> -->
<!--			<origin rpy="0 0 0" xyz="0 0 0" />-->
<!--			<mass value="1.0" />-->
<!--	        <mass value="1.0" />-->
<!--	        <inertia  ixx="1.0" ixy="0.0" ixz="0.0" iyy="1.0" iyz="0.0" izz="1.0"/>-->
<!--		</inertial>-->

    <fake_inertial/>

	</link>
	
<gazebo reference="base_plate"><material>Gazebo/Black</material></gazebo>


	<joint name="base_link_to_link_01" type="fixed">
		<origin rpy="0 0 0" xyz="0 0.0860 0.0020" />
		<parent link="base_plate"/>
		<child link="link_01"/>
	</joint>
	
	<link name="link_01">
		<visual>
			<origin rpy="0 0 0" xyz="0 0 0.0210" />
			<geometry>
				<box size="0.0430 0.0430 0.0420"/>
			</geometry>
		</visual>
		
<!--		<collision>-->
<!--			<origin rpy="0 0 0" xyz="0 0 0.0210"/>-->
<!--			<geometry>-->
<!--				<box size="0.0430 0.0430 0.0420"/>-->
<!--			</geometry>-->
<!--		</collision>-->
<!--		-->
<!--		<inertial> -->
<!--			<origin rpy="0 0 0" xyz="0 0 0.0210" />-->
<!--	        <mass value="1.0" />-->
<!--	        <inertia  ixx="1.0" ixy="0.0" ixz="0.0" iyy="1.0" iyz="0.0" izz="1.0"/>-->
<!--		</inertial>-->

        <fake_inertial/>
	</link>

<gazebo reference="link_01"><material>Gazebo/Black</material></gazebo>

	<joint name="link_01_to_link_02" type="revolute">
		<axis xyz="0 0 1" />
		<limit effort="1000.0" lower="-1.6" upper="1.6" velocity="0.5"/>
		<origin rpy="0 0 0" xyz="0 0 0.0420" />
		<parent link="link_01"/>
		<child link="link_02"/>
	</joint>
	
	<link name="link_02">
		<visual>
			<origin rpy="0 0 0" xyz="0 0 0.015" />
			<geometry>
				<cylinder radius="0.02150" length="0.030"/>
			</geometry>
		</visual>
		
		<collision>
			<origin rpy="0 0 0" xyz="0 0 0.015"/>
			<geometry>
				<cylinder radius="0.02150" length="0.030"/>
			</geometry>
		</collision>
		
		<inertial> 
			<origin rpy="0 0 0" xyz="0 0 0.0150" />
			<mass value="1.0" />
	        <mass value="1.0" />
	        <inertia  ixx="1.0" ixy="0.0" ixz="0.0" iyy="1.0" iyz="0.0" izz="1.0"/>
		</inertial>
<!--        <fake_inertial/>-->
	</link>

<gazebo reference="link_02"><material>Gazebo/Black</material></gazebo>

	<joint name="link_02_to_link_03" type="revolute">
		<axis xyz="1 0 0" />
		<limit effort="1000.0" lower="-1.6" upper="1.6" velocity="0.5"/>
		<origin rpy="-${PI/2} 0 0" xyz="0 0 0.070" />
		<parent link="link_02"/>
		<child link="link_03"/>
	</joint>
	
	<link name="link_03">
		<visual>
			<origin rpy="0 0 0" xyz="0 0 -0.00950" />
			<geometry>
				<box size="0.0850 0.0430 0.0610"/>
			</geometry>
		</visual>
		
		<collision>
			<origin rpy="0 0 0" xyz="0 0 -0.00950"/>
			<geometry>
				<box size="0.0850 0.0430 0.0610"/>
			</geometry>
		</collision>
		
		<inertial> 
			<origin rpy="0 0 0" xyz="0 0 -0.00950" />
	        <mass value="1.0" />
	        <inertia  ixx="1.0" ixy="0.0" ixz="0.0" iyy="1.0" iyz="0.0" izz="1.0"/>
		</inertial>
<!--        <fake_inertial/>-->
	</link>

<gazebo reference="link_03"><material>Gazebo/Black</material></gazebo>

	<joint name="link_03_to_link_04" type="fixed">
		<origin rpy="0 0 0" xyz="0 -0.02150 0" />
		<parent link="link_03"/>
		<child link="link_04"/>
	</joint>
	
	<link name="link_04">
		<visual>
			<origin rpy="1.5708 0 0" xyz="0 -0.0250 0" />
			<geometry>
				<cylinder radius="0.02150" length="0.050"/>
			</geometry>
		</visual>
		
<!--		<collision>-->
<!--			<origin rpy="1.5708 0 0" xyz="0 -0.0250 0"/>-->
<!--			<geometry>-->
<!--				<cylinder radius="0.02150" length="0.050"/>-->
<!--			</geometry>-->
<!--		</collision>-->
<!--		-->
<!--		<inertial> -->
<!--			<origin rpy="1.5708 0 0" xyz="0 -0.0250 0" />-->
<!--	        <mass value="1.0" />-->
<!--	        <inertia  ixx="1.0" ixy="0.0" ixz="0.0" iyy="1.0" iyz="0.0" izz="1.0"/>-->
<!--		</inertial>-->
        <fake_inertial/>
	</link>

<gazebo reference="link_04"><material>Gazebo/Black</material></gazebo>

	<joint name="link_04_to_link_05" type="fixed">
		<origin rpy="0 0 0" xyz="0 -0.025 0" />
		<parent link="link_04"/>
		<child link="link_05"/>
	</joint>
	
	<link name="link_05">
		<visual>
			<origin rpy="0 0 0" xyz="0 0 0.09950" />
			<geometry>
				<cylinder radius="0.0060" length="0.4020"/>
			</geometry>
		</visual>
		
<!--		<collision>-->
<!--			<origin rpy="0 0 0" xyz="0 0 0.09950" />-->
<!--			<geometry>-->
<!--				<cylinder radius="0.0060" length="0.4020"/>-->
<!--			</geometry>-->
<!--		</collision>-->
<!--		-->
<!--		<inertial> -->
<!--			<origin rpy="0 0 0" xyz="0 0 0.09950" />-->
<!--	        <mass value="1.0" />-->
<!--	        <inertia  ixx="1.0" ixy="0.0" ixz="0.0" iyy="1.0" iyz="0.0" izz="1.0"/>-->
<!--		</inertial>-->
        <fake_inertial/>
	</link>



	<joint name="link_05_to_link_06" type="fixed">
		<origin rpy="0 0 0" xyz="0 0 0.13550" />
		<parent link="link_05"/>
		<child link="link_06"/>
	</joint>
	
	<link name="link_06">
		<visual>
			<origin rpy="0 0 0" xyz="0 -0.025 0" />
			<geometry>
				<box size="0.040 0.10 0.020"/>
			</geometry>
		</visual>
		
<!--		<collision>-->
<!--			<origin rpy="0 0 0" xyz="0 -0.025 0"/>-->
<!--			<geometry>-->
<!--				<box size="0.040 0.10 0.020"/>-->
<!--			</geometry>-->
<!--		</collision>-->
<!--		-->
<!--		<inertial> -->
<!--			<origin rpy="0 0 0" xyz="0 -0.025 0" />-->
<!--	        <mass value="1.0" />-->
<!--	        <inertia  ixx="1.0" ixy="0.0" ixz="0.0" iyy="1.0" iyz="0.0" izz="1.0"/>-->
<!--		</inertial>-->
        <fake_inertial/>
	</link>
	
<gazebo reference="link_06"><material>Gazebo/Black</material></gazebo>

	<joint name="link_06_to_link_07" type="fixed">
		<origin rpy="0 0 0" xyz="0 0 0.0470" />
		<parent link="link_06"/>
		<child link="link_07"/>
	</joint>
	
	<link name="link_07">
		<visual>
			<origin rpy="0 0 0" xyz="0 -0.025 0" />
			<geometry>
				<box size="0.040 0.10 0.020"/>
			</geometry>
		</visual>
		
<!--		<collision>-->
<!--			<origin rpy="0 0 0" xyz="0 -0.025 0"/>-->
<!--			<geometry>-->
<!--				<box size="0.040 0.10 0.020"/>-->
<!--			</geometry>-->
<!--		</collision>-->
<!--		-->
<!--		<inertial> -->
<!--			<origin rpy="0 0 0" xyz="0 -0.025 0" />-->
<!--	        <mass value="1.0" />-->
<!--	        <inertia  ixx="1.0" ixy="0.0" ixz="0.0" iyy="1.0" iyz="0.0" izz="1.0"/>-->
<!--		</inertial>-->
        <fake_inertial/>
	</link>
	
<gazebo reference="link_07"><material>Gazebo/Black</material></gazebo>

	<joint name="link_07_to_link_08" type="fixed">
		<origin rpy="0 0 0" xyz="0 -0.050 0" />
		<parent link="link_07"/>
		<child link="link_08"/>
	</joint>
	
	<link name="link_08">
		<visual>
			<origin rpy="0 0 0" xyz="0 0 0.0910" />
			<geometry>
				<cylinder radius="0.0060" length="0.5280"/>
			</geometry>
		</visual>
<!--		<collision>-->
<!--			<origin rpy="0 0 0" xyz="0 0 0.0910" />-->
<!--			<geometry>-->
<!--				<cylinder radius="0.0060" length="0.5280"/>-->
<!--			</geometry>-->
<!--		</collision>-->
<!--		-->
<!--		<inertial> -->
<!--			<origin rpy="0 0 0" xyz="0 0 0.0910" />-->
<!--	        <mass value="1.0" />-->
<!--	        <inertia  ixx="1.0" ixy="0.0" ixz="0.0" iyy="1.0" iyz="0.0" izz="1.0"/>-->
<!--		</inertial>-->
        <fake_inertial/>

	</link>

  <xacro:include filename="sherpa_sprayer_transmission.xacro" />

</robot>
